Workbook

Sheet Start here
A1: LGB — customer data collection (for Sharon)
A3: Open in Excel or Numbers — not in a code editor. Formulas need Excel 365 or Excel 2021+.
A5: Fill in this order:
A6: 1. Who we invoice
A7: 2. Divisions — MOI managers + emails
A8: 3. Companies — basics (division, LOA, billing)
A9: 4. Client contacts — who fills MOI, signs MOA, starts requests
A10: 5. Company MOA setup — pick workflow per company; fill name/email blanks
A11: 6. Contracts — packages + extra LGB staff only
A13: MOA workflows (read MOA workflow steps + MOA role matrix tabs):
A14: • Each company can use a different MOA workflow.
A15: • Row 2 on Company MOA setup shows what each column needs (Fill / Auto / —).
... A20: Delete example rows before import.

Sheet MOA workflow steps
A1: MOA workflow | B1: Step | C1: Approver role | D1: Who Sharon fills
A2: MOA — No LOA | B2: 1 | C2: Senior Manager, Company Secretarial | D2: LGB internal (fixed)
A3: MOA — No LOA | B3: 2 | C3: Project initiator | D3: Per company — client contact
A4: MOA — No LOA | B4: 3 | C4: Head of Finance / CFO | D4: Per company — when finance-related
A5: MOA — No LOA | B5: 4 | C5: CEO / COO / GM | D5: Per company — when finance / share movement
A6: MOA — No LOA | B6: 5 | C6: Ms Teh | D6: LGB internal (bank signatory matters)
A7: MOA — No LOA | B7: 6 | C7: Full Board | D7: Per company — board member names
A8: MOA — No LOA | B8: 7 | C8: DLCM | D8: LGB / external (fixed)
A9: MOA — With LOA | B9: 1 | C9: Senior Manager, Company Secretarial | D9: LGB internal (fixed)
A10: MOA — With LOA | B10: 2 | C10: Project initiator | D10: Per company — client contact
A11: MOA — With LOA | B11: 3 | C11: Head of Finance / CFO | D11: Per company — when finance-related
A12: MOA — With LOA | B12: 4 | C12: Ms Teh | D12: LGB internal (bank signatory matters)
A13: MOA — With LOA | B13: 5 | C13: DLCM — all bank matters | D13: LGB / external (fixed)
... A20: MOA — SWM Group | B20: 7 | C20: Ms Teh | D20: LGB internal (bank signatory matters)

Sheet MOA role matrix
A1: Role slot | B1: MOA — No LOA | C1: MOA — With LOA | D1: MOA — SWM Group
A2: Project initiator | B2: Fill | C2: Fill | D2: Fill
A3: MOA signers (client) | B3: Auto | C3: Auto | D3: Auto
A4: CFO / Head of Finance | B4: If finance | C4: If finance | D4: If finance
A5: CEO / COO / GM | B5: If finance | C5: — | D5: —
A6: Board member 1 | B6: Fill | C6: — | D6: —
A7: Board member 2 | B7: Fill | C7: — | D7: —
A8: LOA holder 1 | B8: — | C8: — | D8: Fill
A9: LOA holder 2 | B9: — | C9: — | D9: Fill
A10: Senior Manager CoSec | B10: LGB fixed | C10: LGB fixed | D10: LGB fixed
A11: Division MOI managers | B11: Auto | C11: Auto | D11: Auto
A12: Ms Teh (bank) | B12: If bank | C12: If bank | D12: If bank
A13: DLCM | B13: LGB fixed | C13: LGB fixed | D13: —
A15: Legend: Fill = Sharon types name/email | Auto = formula from contacts | If finance = only when matter is finance-related | LGB fixed = system handles

Sheet Divisions
A1: Division | B1: Default MOA workflow | C1: MOI recommender 1 name | D1: MOI recommender 1 email | E1: MOI recommender 2 name | F1: MOI recommender 2 email | G1: MOI recommender 3 name | H1: MOI recommender 3 email | I1: MOI recommender 4 name | J1: MOI recommender 4 email | K1: Notes
A2: LGB | B2: MOA — No LOA | C2: Tai | E2: Sam
A3: LGB INS | B3: MOA — No LOA | C3: Steven | E3: Tiew Siong Yi
A4: Exitra | B4: MOA — No LOA | C4: Kevin Teoh | E4: Tay | G4: Jonas
A5: Bellworth & London | B5: MOA — No LOA | C5: Kevin Kuok | E5: Jaslyn | G5: Wong Wai Leng | I5: Evelyn
A6: UER | B6: MOA — No LOA | C6: Sam Lau
A7: Parkwood | B7: MOA — No LOA | C7: Danny Ng | E7: Casper Wong
A8: SWM | B8: MOA — SWM Group | C8: Shirley | E8: Bin | G8: Yvonne | I8: Thomas
A9: DLAL | B9: MOA — No LOA
A10: DLCM | B10: MOA — With LOA
A11: DLCM & KK | B11: MOA — With LOA
A12: DLCM & SEAN | B12: MOA — With LOA
A13: HOLD ON | B13: MOA — No LOA
A14: Nominees | B14: MOA — No LOA
A15: TCB | B15: MOA — No LOA
A16: KK | B16: MOA — With LOA
A17: SEAN | B17: MOA — With LOA
A18: ISHAK | B18: MOA — No LOA
A19: JANICE | B19: MOA — No LOA

Sheet Who we invoice
A1: Name on invoice / account | B1: Used for | C1: Active | D1: Notes
A2: Acme Corp | B2: Invoice and charge | C2: Y | D2: Example — delete this row

Sheet Companies
A1: Company name | B1: Main contact name | C1: Main contact email | D1: Main contact phone | E1: Division | F1: MOA workflow (from MOA setup) | G1: COSEC client? | H1: Has Limit of Authority (LOA)? | I1: LOA holder names (if Y) | J1: Invoice to | K1: Bill to | L1: Division MOI managers (auto) | M1: Notes
A2: Acme Corp | B2: Sarah Johnson | C2: sarah.j@acme.com | D2: +60 12-345 6789 | E2: LGB | F2: =IFERROR(INDEX('Company MOA setup'!$B$3:$B$500,MATCH($A2,'Company MOA setup'!$A$3:$A$500,0)),"Division default") | G2: Y | H2: N | J2: Acme Corp | K2: Acme Corp | L2: =IF($E2="","",TRIM(IFERROR(INDEX(Divisions!$C$3:$C$50,MATCH($E2,Divisions!$A$3:$A$50,0)),"")&IF(IFERROR(INDEX(Divisions!$E$3:$E$50,MATCH($E2,Divisions!$A$3:$A$50,0)),"")<>"",", "&IFERROR(INDEX(Divisions!$E$3:$E$50,MATCH($E2,Divisions!$A$3:$A$50,0)),""),"")&IF(IFERROR(INDEX(Divisions!$G$3:$G$50,MATCH($E2,Divisions!$A$3:$A$50,0)),"")<>"",", "&IFERROR(INDEX(Divisions!$G$3:$G$50,MATCH($E2,Divisions!$A$3:$A$50,0)),""),"")&IF(IFERROR(INDEX(Divisions!$I$3:$I$50,MATCH($E2,Divisions!$A$3:$A$50,0)),"")<>"",", "&IFERROR(INDEX(Divisions!$I$3:$I$50,MATCH($E2,Divisions!$A$3:$A$50,0)),""),""))) | M2: Example — delete this row
F3: =IFERROR(INDEX('Company MOA setup'!$B$3:$B$500,MATCH($A3,'Company MOA setup'!$A$3:$A$500,0)),"Division default") | L3: =IF($E3="","",TRIM(IFERROR(INDEX(Divisions!$C$3:$C$50,MATCH($E3,Divisions!$A$3:$A$50,0)),"")&IF(IFERROR(INDEX(Divisions!$E$3:$E$50,MATCH($E3,Divisions!$A$3:$A$50,0)),"")<>"",", "&IFERROR(INDEX(Divisions!$E$3:$E$50,MATCH($E3,Divisions!$A$3:$A$50,0)),""),"")&IF(IFERROR(INDEX(Divisions!$G$3:$G$50,MATCH($E3,Divisions!$A$3:$A$50,0)),"")<>"",", "&IFERROR(INDEX(Divisions!$G$3:$G$50,MATCH($E3,Divisions!$A$3:$A$50,0)),""),"")&IF(IFERROR(INDEX(Divisions!$I$3:$I$50,MATCH($E3,Divisions!$A$3:$A$50,0)),"")<>"",", "&IFERROR(INDEX(Divisions!$I$3:$I$50,MATCH($E3,Divisions!$A$3:$A$50,0)),""),"")))
F4: =IFERROR(INDEX('Company MOA setup'!$B$3:$B$500,MATCH($A4,'Company MOA setup'!$A$3:$A$500,0)),"Division default") | L4: =IF($E4="","",TRIM(IFERROR(INDEX(Divisions!$C$3:$C$50,MATCH($E4,Divisions!$A$3:$A$50,0)),"")&IF(IFERROR(INDEX(Divisions!$E$3:$E$50,MATCH($E4,Divisions!$A$3:$A$50,0)),"")<>"",", "&IFERROR(INDEX(Divisions!$E$3:$E$50,MATCH($E4,Divisions!$A$3:$A$50,0)),""),"")&IF(IFERROR(INDEX(Divisions!$G$3:$G$50,MATCH($E4,Divisions!$A$3:$A$50,0)),"")<>"",", "&IFERROR(INDEX(Divisions!$G$3:$G$50,MATCH($E4,Divisions!$A$3:$A$50,0)),""),"")&IF(IFERROR(INDEX(Divisions!$I$3:$I$50,MATCH($E4,Divisions!$A$3:$A$50,0)),"")<>"",", "&IFERROR(INDEX(Divisions!$I$3:$I$50,MATCH($E4,Divisions!$A$3:$A$50,0)),""),"")))
F5: =IFERROR(INDEX('Company MOA setup'!$B$3:$B$500,MATCH($A5,'Company MOA setup'!$A$3:$A$500,0)),"Division default") | L5: =IF($E5="","",TRIM(IFERROR(INDEX(Divisions!$C$3:$C$50,MATCH($E5,Divisions!$A$3:$A$50,0)),"")&IF(IFERROR(INDEX(Divisions!$E$3:$E$50,MATCH($E5,Divisions!$A$3:$A$50,0)),"")<>"",", "&IFERROR(INDEX(Divisions!$E$3:$E$50,MATCH($E5,Divisions!$A$3:$A$50,0)),""),"")&IF(IFERROR(INDEX(Divisions!$G$3:$G$50,MATCH($E5,Divisions!$A$3:$A$50,0)),"")<>"",", "&IFERROR(INDEX(Divisions!$G$3:$G$50,MATCH($E5,Divisions!$A$3:$A$50,0)),""),"")&IF(IFERROR(INDEX(Divisions!$I$3:$I$50,MATCH($E5,Divisions!$A$3:$A$50,0)),"")<>"",", "&IFERROR(INDEX(Divisions!$I$3:$I$50,MATCH($E5,Divisions!$A$3:$A$50,0)),""),"")))
F6: =IFERROR(INDEX('Company MOA setup'!$B$3:$B$500,MATCH($A6,'Company MOA setup'!$A$3:$A$500,0)),"Division default") | L6: =IF($E6="","",TRIM(IFERROR(INDEX(Divisions!$C$3:$C$50,MATCH($E6,Divisions!$A$3:$A$50,0)),"")&IF(IFERROR(INDEX(Divisions!$E$3:$E$50,MATCH($E6,Divisions!$A$3:$A$50,0)),"")<>"",", "&IFERROR(INDEX(Divisions!$E$3:$E$50,MATCH($E6,Divisions!$A$3:$A$50,0)),""),"")&IF(IFERROR(INDEX(Divisions!$G$3:$G$50,MATCH($E6,Divisions!$A$3:$A$50,0)),"")<>"",", "&IFERROR(INDEX(Divisions!$G$3:$G$50,MATCH($E6,Divisions!$A$3:$A$50,0)),""),"")&IF(IFERROR(INDEX(Divisions!$I$3:$I$50,MATCH($E6,Divisions!$A$3:$A$50,0)),"")<>"",", "&IFERROR(INDEX(Divisions!$I$3:$I$50,MATCH($E6,Divisions!$A$3:$A$50,0)),""),"")))
F7: =IFERROR(INDEX('Company MOA setup'!$B$3:$B$500,MATCH($A7,'Company MOA setup'!$A$3:$A$500,0)),"Division default") | L7: =IF($E7="","",TRIM(IFERROR(INDEX(Divisions!$C$3:$C$50,MATCH($E7,Divisions!$A$3:$A$50,0)),"")&IF(IFERROR(INDEX(Divisions!$E$3:$E$50,MATCH($E7,Divisions!$A$3:$A$50,0)),"")<>"",", "&IFERROR(INDEX(Divisions!$E$3:$E$50,MATCH($E7,Divisions!$A$3:$A$50,0)),""),"")&IF(IFERROR(INDEX(Divisions!$G$3:$G$50,MATCH($E7,Divisions!$A$3:$A$50,0)),"")<>"",", "&IFERROR(INDEX(Divisions!$G$3:$G$50,MATCH($E7,Divisions!$A$3:$A$50,0)),""),"")&IF(IFERROR(INDEX(Divisions!$I$3:$I$50,MATCH($E7,Divisions!$A$3:$A$50,0)),"")<>"",", "&IFERROR(INDEX(Divisions!$I$3:$I$50,MATCH($E7,Divisions!$A$3:$A$50,0)),""),"")))
F8: =IFERROR(INDEX('Company MOA setup'!$B$3:$B$500,MATCH($A8,'Company MOA setup'!$A$3:$A$500,0)),"Division default") | L8: =IF($E8="","",TRIM(IFERROR(INDEX(Divisions!$C$3:$C$50,MATCH($E8,Divisions!$A$3:$A$50,0)),"")&IF(IFERROR(INDEX(Divisions!$E$3:$E$50,MATCH($E8,Divisions!$A$3:$A$50,0)),"")<>"",", "&IFERROR(INDEX(Divisions!$E$3:$E$50,MATCH($E8,Divisions!$A$3:$A$50,0)),""),"")&IF(IFERROR(INDEX(Divisions!$G$3:$G$50,MATCH($E8,Divisions!$A$3:$A$50,0)),"")<>"",", "&IFERROR(INDEX(Divisions!$G$3:$G$50,MATCH($E8,Divisions!$A$3:$A$50,0)),""),"")&IF(IFERROR(INDEX(Divisions!$I$3:$I$50,MATCH($E8,Divisions!$A$3:$A$50,0)),"")<>"",", "&IFERROR(INDEX(Divisions!$I$3:$I$50,MATCH($E8,Divisions!$A$3:$A$50,0)),""),"")))
F9: =IFERROR(INDEX('Company MOA setup'!$B$3:$B$500,MATCH($A9,'Company MOA setup'!$A$3:$A$500,0)),"Division default") | L9: =IF($E9="","",TRIM(IFERROR(INDEX(Divisions!$C$3:$C$50,MATCH($E9,Divisions!$A$3:$A$50,0)),"")&IF(IFERROR(INDEX(Divisions!$E$3:$E$50,MATCH($E9,Divisions!$A$3:$A$50,0)),"")<>"",", "&IFERROR(INDEX(Divisions!$E$3:$E$50,MATCH($E9,Divisions!$A$3:$A$50,0)),""),"")&IF(IFERROR(INDEX(Divisions!$G$3:$G$50,MATCH($E9,Divisions!$A$3:$A$50,0)),"")<>"",", "&IFERROR(INDEX(Divisions!$G$3:$G$50,MATCH($E9,Divisions!$A$3:$A$50,0)),""),"")&IF(IFERROR(INDEX(Divisions!$I$3:$I$50,MATCH($E9,Divisions!$A$3:$A$50,0)),"")<>"",", "&IFERROR(INDEX(Divisions!$I$3:$I$50,MATCH($E9,Divisions!$A$3:$A$50,0)),""),"")))
F10: =IFERROR(INDEX('Company MOA setup'!$B$3:$B$500,MATCH($A10,'Company MOA setup'!$A$3:$A$500,0)),"Division default") | L10: =IF($E10="","",TRIM(IFERROR(INDEX(Divisions!$C$3:$C$50,MATCH($E10,Divisions!$A$3:$A$50,0)),"")&IF(IFERROR(INDEX(Divisions!$E$3:$E$50,MATCH($E10,Divisions!$A$3:$A$50,0)),"")<>"",", "&IFERROR(INDEX(Divisions!$E$3:$E$50,MATCH($E10,Divisions!$A$3:$A$50,0)),""),"")&IF(IFERROR(INDEX(Divisions!$G$3:$G$50,MATCH($E10,Divisions!$A$3:$A$50,0)),"")<>"",", "&IFERROR(INDEX(Divisions!$G$3:$G$50,MATCH($E10,Divisions!$A$3:$A$50,0)),""),"")&IF(IFERROR(INDEX(Divisions!$I$3:$I$50,MATCH($E10,Divisions!$A$3:$A$50,0)),"")<>"",", "&IFERROR(INDEX(Divisions!$I$3:$I$50,MATCH($E10,Divisions!$A$3:$A$50,0)),""),"")))
F11: =IFERROR(INDEX('Company MOA setup'!$B$3:$B$500,MATCH($A11,'Company MOA setup'!$A$3:$A$500,0)),"Division default") | L11: =IF($E11="","",TRIM(IFERROR(INDEX(Divisions!$C$3:$C$50,MATCH($E11,Divisions!$A$3:$A$50,0)),"")&IF(IFERROR(INDEX(Divisions!$E$3:$E$50,MATCH($E11,Divisions!$A$3:$A$50,0)),"")<>"",", "&IFERROR(INDEX(Divisions!$E$3:$E$50,MATCH($E11,Divisions!$A$3:$A$50,0)),""),"")&IF(IFERROR(INDEX(Divisions!$G$3:$G$50,MATCH($E11,Divisions!$A$3:$A$50,0)),"")<>"",", "&IFERROR(INDEX(Divisions!$G$3:$G$50,MATCH($E11,Divisions!$A$3:$A$50,0)),""),"")&IF(IFERROR(INDEX(Divisions!$I$3:$I$50,MATCH($E11,Divisions!$A$3:$A$50,0)),"")<>"",", "&IFERROR(INDEX(Divisions!$I$3:$I$50,MATCH($E11,Divisions!$A$3:$A$50,0)),""),"")))
F12: =IFERROR(INDEX('Company MOA setup'!$B$3:$B$500,MATCH($A12,'Company MOA setup'!$A$3:$A$500,0)),"Division default") | L12: =IF($E12="","",TRIM(IFERROR(INDEX(Divisions!$C$3:$C$50,MATCH($E12,Divisions!$A$3:$A$50,0)),"")&IF(IFERROR(INDEX(Divisions!$E$3:$E$50,MATCH($E12,Divisions!$A$3:$A$50,0)),"")<>"",", "&IFERROR(INDEX(Divisions!$E$3:$E$50,MATCH($E12,Divisions!$A$3:$A$50,0)),""),"")&IF(IFERROR(INDEX(Divisions!$G$3:$G$50,MATCH($E12,Divisions!$A$3:$A$50,0)),"")<>"",", "&IFERROR(INDEX(Divisions!$G$3:$G$50,MATCH($E12,Divisions!$A$3:$A$50,0)),""),"")&IF(IFERROR(INDEX(Divisions!$I$3:$I$50,MATCH($E12,Divisions!$A$3:$A$50,0)),"")<>"",", "&IFERROR(INDEX(Divisions!$I$3:$I$50,MATCH($E12,Divisions!$A$3:$A$50,0)),""),"")))
F13: =IFERROR(INDEX('Company MOA setup'!$B$3:$B$500,MATCH($A13,'Company MOA setup'!$A$3:$A$500,0)),"Division default") | L13: =IF($E13="","",TRIM(IFERROR(INDEX(Divisions!$C$3:$C$50,MATCH($E13,Divisions!$A$3:$A$50,0)),"")&IF(IFERROR(INDEX(Divisions!$E$3:$E$50,MATCH($E13,Divisions!$A$3:$A$50,0)),"")<>"",", "&IFERROR(INDEX(Divisions!$E$3:$E$50,MATCH($E13,Divisions!$A$3:$A$50,0)),""),"")&IF(IFERROR(INDEX(Divisions!$G$3:$G$50,MATCH($E13,Divisions!$A$3:$A$50,0)),"")<>"",", "&IFERROR(INDEX(Divisions!$G$3:$G$50,MATCH($E13,Divisions!$A$3:$A$50,0)),""),"")&IF(IFERROR(INDEX(Divisions!$I$3:$I$50,MATCH($E13,Divisions!$A$3:$A$50,0)),"")<>"",", "&IFERROR(INDEX(Divisions!$I$3:$I$50,MATCH($E13,Divisions!$A$3:$A$50,0)),""),"")))
F14: =IFERROR(INDEX('Company MOA setup'!$B$3:$B$500,MATCH($A14,'Company MOA setup'!$A$3:$A$500,0)),"Division default") | L14: =IF($E14="","",TRIM(IFERROR(INDEX(Divisions!$C$3:$C$50,MATCH($E14,Divisions!$A$3:$A$50,0)),"")&IF(IFERROR(INDEX(Divisions!$E$3:$E$50,MATCH($E14,Divisions!$A$3:$A$50,0)),"")<>"",", "&IFERROR(INDEX(Divisions!$E$3:$E$50,MATCH($E14,Divisions!$A$3:$A$50,0)),""),"")&IF(IFERROR(INDEX(Divisions!$G$3:$G$50,MATCH($E14,Divisions!$A$3:$A$50,0)),"")<>"",", "&IFERROR(INDEX(Divisions!$G$3:$G$50,MATCH($E14,Divisions!$A$3:$A$50,0)),""),"")&IF(IFERROR(INDEX(Divisions!$I$3:$I$50,MATCH($E14,Divisions!$A$3:$A$50,0)),"")<>"",", "&IFERROR(INDEX(Divisions!$I$3:$I$50,MATCH($E14,Divisions!$A$3:$A$50,0)),""),"")))
... F500: =IFERROR(INDEX('Company MOA setup'!$B$3:$B$500,MATCH($A500,'Company MOA setup'!$A$3:$A$500,0)),"Division default") | L500: =IF($E500="","",TRIM(IFERROR(INDEX(Divisions!$C$3:$C$50,MATCH($E500,Divisions!$A$3:$A$50,0)),"")&IF(IFERROR(INDEX(Divisions!$E$3:$E$50,MATCH($E500,Divisions!$A$3:$A$50,0)),"")<>"",", "&IFERROR(INDEX(Divisions!$E$3:$E$50,MATCH($E500,Divisions!$A$3:$A$50,0)),""),"")&IF(IFERROR(INDEX(Divisions!$G$3:$G$50,MATCH($E500,Divisions!$A$3:$A$50,0)),"")<>"",", "&IFERROR(INDEX(Divisions!$G$3:$G$50,MATCH($E500,Divisions!$A$3:$A$50,0)),""),"")&IF(IFERROR(INDEX(Divisions!$I$3:$I$50,MATCH($E500,Divisions!$A$3:$A$50,0)),"")<>"",", "&IFERROR(INDEX(Divisions!$I$3:$I$50,MATCH($E500,Divisions!$A$3:$A$50,0)),""),"")))

Sheet Client contacts
A1: Company name | B1: Person name | C1: Email | D1: Phone | E1: Fills in MOI? | F1: Approves MOI (client)? | G1: Signs MOA? | H1: Usually starts the request? | I1: Notes
A2: Acme Corp | B2: Dan Ra | C2: dra@lgb.test | D2: +60 11-111 1111 | E2: Y | F2: Y | G2: Y | H2: Y | I2: Example — delete
A3: Acme Corp | B3: Daniel Ra | C3: dra2@lgb.test | E3: Y | F3: N | G3: Y | H3: N | I3: Example — delete
A4: Acme Corp | B4: Dra Three | C4: dra3@lgb.test | E4: N | F4: Y | G4: Y | H4: N | I4: Example — delete

Sheet Company MOA setup
A1: Company name | B1: MOA workflow | C1: Roles in this workflow (auto) | D1: Project initiator name (auto) | E1: Project initiator email (auto) | F1: MOA signer 1 name (auto) | G1: MOA signer 1 email (auto) | H1: MOA signer 2 name (auto) | I1: MOA signer 2 email (auto) | J1: CFO / Finance name | K1: CFO / Finance email | L1: CEO / GM name | M1: CEO / GM email | N1: Board member 1 name | O1: Board member 1 email | P1: Board member 2 name | Q1: Board member 2 email | R1: LOA holder 1 name (auto) | S1: LOA holder 1 email | T1: LOA holder 2 name | U1: LOA holder 2 email | V1: LGB prepared-by email | W1: LGB vetted-by email | X1: Notes
A2: Column guide (per workflow) → | D2: =IF($B3="","",INDEX('MOA role matrix'!$B$2:$D$13,1,MATCH($B3,'MOA role matrix'!$B$1:$D$1,0))) | F2: =IF($B3="","",INDEX('MOA role matrix'!$B$2:$D$13,2,MATCH($B3,'MOA role matrix'!$B$1:$D$1,0))) | J2: =IF($B3="","",INDEX('MOA role matrix'!$B$2:$D$13,3,MATCH($B3,'MOA role matrix'!$B$1:$D$1,0))) | L2: =IF($B3="","",INDEX('MOA role matrix'!$B$2:$D$13,4,MATCH($B3,'MOA role matrix'!$B$1:$D$1,0))) | N2: =IF($B3="","",INDEX('MOA role matrix'!$B$2:$D$13,5,MATCH($B3,'MOA role matrix'!$B$1:$D$1,0))) | P2: =IF($B3="","",INDEX('MOA role matrix'!$B$2:$D$13,6,MATCH($B3,'MOA role matrix'!$B$1:$D$1,0))) | R2: =IF($B3="","",INDEX('MOA role matrix'!$B$2:$D$13,7,MATCH($B3,'MOA role matrix'!$B$1:$D$1,0))) | T2: =IF($B3="","",INDEX('MOA role matrix'!$B$2:$D$13,8,MATCH($B3,'MOA role matrix'!$B$1:$D$1,0)))
A3: Acme Corp | B3: MOA — No LOA | C3: =IF($B3="","",TRIM(IF(INDEX('MOA role matrix'!$B$2:$D$13,1,MATCH($B3,'MOA role matrix'!$B$1:$D$1,0))="Fill","Project initiator, ","")IF(INDEX('MOA role matrix'!$B$2:$D$13,1,MATCH($B3,'MOA role matrix'!$B$1:$D$1,0))="If finance","Project initiator (if finance), ","")IF(INDEX('MOA role matrix'!$B$2:$D$13,1,MATCH($B3,'MOA role matrix'!$B$1:$D$1,0))="Auto","Project initiator (auto), ","")IF(INDEX('MOA role matrix'!$B$2:$D$13,2,MATCH($B3,'MOA role matrix'!$B$1:$D$1,0))="Fill","MOA signers (client), ","")IF(INDEX('MOA role matrix'!$B$2:$D$13,2,MATCH($B3,'MOA role matrix'!$B$1:$D$1,0))="If finance","MOA signers (client) (if finance), ","")IF(INDEX('MOA role matrix'!$B$2:$D$13,2,MATCH($B3,'MOA role matrix'!$B$1:$D$1,0))="Auto","MOA signers (client) (auto), ","")IF(INDEX('MOA role matrix'!$B$2:$D$13,3,MATCH($B3,'MOA role matrix'!$B$1:$D$1,0))="Fill","CFO / Head of Finance, ","")IF(INDEX('MOA role matrix'!$B$2:$D$13,3,MATCH($B3,'MOA role matrix'!$B$1:$D$1,0))="If finance","CFO / Head of Finance (if finance), ","")IF(INDEX('MOA role matrix'!$B$2:$D$13,3,MATCH($B3,'MOA role matrix'!$B$1:$D$1,0))="Auto","CFO / Head of Finance (auto), ","")IF(INDEX('MOA role matrix'!$B$2:$D$13,4,MATCH($B3,'MOA role matrix'!$B$1:$D$1,0))="Fill","CEO / COO / GM, ","")IF(INDEX('MOA role matrix'!$B$2:$D$13,4,MATCH($B3,'MOA role matrix'!$B$1:$D$1,0))="If finance","CEO / COO / GM (if finance), ","")IF(INDEX('MOA role matrix'!$B$2:$D$13,4,MATCH($B3,'MOA role matrix'!$B$1:$D$1,0))="Auto","CEO / COO / GM (auto), ","")IF(INDEX('MOA role matrix'!$B$2:$D$13,5,MATCH($B3,'MOA role matrix'!$B$1:$D$1,0))="Fill","Board member 1, ","")IF(INDEX('MOA role matrix'!$B$2:$D$13,5,MATCH($B3,'MOA role matrix'!$B$1:$D$1,0))="If finance","Board member 1 (if finance), ","")IF(INDEX('MOA role matrix'!$B$2:$D$13,5,MATCH($B3,'MOA role matrix'!$B$1:$D$1,0))="Auto","Board member 1 (auto), ","")IF(INDEX('MOA role matrix'!$B$2:$D$13,6,MATCH($B3,'MOA role matrix'!$B$1:$D$1,0))="Fill","Board member 2, ","")IF(INDEX('MOA role matrix'!$B$2:$D$13,6,MATCH($B3,'MOA role matrix'!$B$1:$D$1,0))="If finance","Board member 2 (if finance), ","")IF(INDEX('MOA role matrix'!$B$2:$D$13,6,MATCH($B3,'MOA role matrix'!$B$1:$D$1,0))="Auto","Board member 2 (auto), ","")IF(INDEX('MOA role matrix'!$B$2:$D$13,7,MATCH($B3,'MOA role matrix'!$B$1:$D$1,0))="Fill","LOA holder 1, ","")IF(INDEX('MOA role matrix'!$B$2:$D$13,7,MATCH($B3,'MOA role matrix'!$B$1:$D$1,0))="If finance","LOA holder 1 (if finance), ","")IF(INDEX('MOA role matrix'!$B$2:$D$13,7,MATCH($B3,'MOA role matrix'!$B$1:$D$1,0))="Auto","LOA holder 1 (auto), ","")IF(INDEX('MOA role matrix'!$B$2:$D$13,8,MATCH($B3,'MOA role matrix'!$B$1:$D$1,0))="Fill","LOA holder 2, ","")IF(INDEX('MOA role matrix'!$B$2:$D$13,8,MATCH($B3,'MOA role matrix'!$B$1:$D$1,0))="If finance","LOA holder 2 (if finance), ","")IF(INDEX('MOA role matrix'!$B$2:$D$13,8,MATCH($B3,'MOA role matrix'!$B$1:$D$1,0))="Auto","LOA holder 2 (auto), ","")IF(INDEX('MOA role matrix'!$B$2:$D$13,9,MATCH($B3,'MOA role matrix'!$B$1:$D$1,0))="Fill","Senior Manager CoSec, ","")IF(INDEX('MOA role matrix'!$B$2:$D$13,9,MATCH($B3,'MOA role matrix'!$B$1:$D$1,0))="If finance","Senior Manager CoSec (if finance), ","")IF(INDEX('MOA role matrix'!$B$2:$D$13,9,MATCH($B3,'MOA role matrix'!$B$1:$D$1,0))="Auto","Senior Manager CoSec (auto), ","")IF(INDEX('MOA role matrix'!$B$2:$D$13,10,MATCH($B3,'MOA role matrix'!$B$1:$D$1,0))="Fill","Division MOI managers, ","")IF(INDEX('MOA role matrix'!$B$2:$D$13,10,MATCH($B3,'MOA role matrix'!$B$1:$D$1,0))="If finance","Division MOI managers (if finance), ","")IF(INDEX('MOA role matrix'!$B$2:$D$13,10,MATCH($B3,'MOA role matrix'!$B$1:$D$1,0))="Auto","Division MOI managers (auto), ","")IF(INDEX('MOA role matrix'!$B$2:$D$13,11,MATCH($B3,'MOA role matrix'!$B$1:$D$1,0))="Fill","Ms Teh (bank), ","")IF(INDEX('MOA role matrix'!$B$2:$D$13,11,MATCH($B3,'MOA role matrix'!$B$1:$D$1,0))="If finance","Ms Teh (bank) (if finance), ","")IF(INDEX('MOA role matrix'!$B$2:$D$13,11,MATCH($B3,'MOA role matrix'!$B$1:$D$1,0))="Auto","Ms Teh (bank) (auto), ","")IF(INDEX('MOA role matrix'!$B$2:$D$13,12,MATCH($B3,'MOA role matrix'!$B$1:$D$1,0))="Fill","DLCM, ","")IF(INDEX('MOA role matrix'!$B$2:$D$13,12,MATCH($B3,'MOA role matrix'!$B$1:$D$1,0))="If finance","DLCM (if finance), ","")IF(INDEX('MOA role matrix'!$B$2:$D$13,12,MATCH($B3,'MOA role matrix'!$B$1:$D$1,0))="Auto","DLCM (auto), ",""))) | D3: =IF($A3="","",IFERROR(INDEX(FILTER('Client contacts'!$B$2:$B$500,('Client contacts'!$A$2:$A$500=$A3)*('Client contacts'!$H$2:$H$500="Y"),""),1),"")) | E3: =IF($A3="","",IFERROR(INDEX(FILTER('Client contacts'!$C$2:$C$500,('Client contacts'!$A$2:$A$500=$A3)*('Client contacts'!$H$2:$H$500="Y"),""),1),"")) | F3: =IF($A3="","",IFERROR(INDEX(FILTER('Client contacts'!$B$2:$B$500,('Client contacts'!$A$2:$A$500=$A3)*('Client contacts'!$G$2:$G$500="Y"),""),1),"")) | G3: =IF($A3="","",IFERROR(INDEX(FILTER('Client contacts'!$C$2:$C$500,('Client contacts'!$A$2:$A$500=$A3)*('Client contacts'!$G$2:$G$500="Y"),""),1),"")) | H3: =IF($A3="","",IFERROR(INDEX(FILTER('Client contacts'!$B$2:$B$500,('Client contacts'!$A$2:$A$500=$A3)*('Client contacts'!$G$2:$G$500="Y"),""),2),"")) | I3: =IF($A3="","",IFERROR(INDEX(FILTER('Client contacts'!$C$2:$C$500,('Client contacts'!$A$2:$A$500=$A3)*('Client contacts'!$G$2:$G$500="Y"),""),2),"")) | L3: Jane CEO | M3: ceo@acme.com | N3: Director One | R3: =IF($A3="","",IFERROR(INDEX(Companies!$I$2:$I$500,MATCH($A3,Companies!$A$2:$A$500,0)),"")) | V3: nadia@lgb.test | W3: nita@lgb.test | X3: Example — delete this row
C4: =IF($B4="","",TRIM(IF(INDEX('MOA role matrix'!$B$2:$D$13,1,MATCH($B4,'MOA role matrix'!$B$1:$D$1,0))="Fill","Project initiator, ","")IF(INDEX('MOA role matrix'!$B$2:$D$13,1,MATCH($B4,'MOA role matrix'!$B$1:$D$1,0))="If finance","Project initiator (if finance), ","")IF(INDEX('MOA role matrix'!$B$2:$D$13,1,MATCH($B4,'MOA role matrix'!$B$1:$D$1,0))="Auto","Project initiator (auto), ","")IF(INDEX('MOA role matrix'!$B$2:$D$13,2,MATCH($B4,'MOA role matrix'!$B$1:$D$1,0))="Fill","MOA signers (client), ","")IF(INDEX('MOA role matrix'!$B$2:$D$13,2,MATCH($B4,'MOA role matrix'!$B$1:$D$1,0))="If finance","MOA signers (client) (if finance), ","")IF(INDEX('MOA role matrix'!$B$2:$D$13,2,MATCH($B4,'MOA role matrix'!$B$1:$D$1,0))="Auto","MOA signers (client) (auto), ","")IF(INDEX('MOA role matrix'!$B$2:$D$13,3,MATCH($B4,'MOA role matrix'!$B$1:$D$1,0))="Fill","CFO / Head of Finance, ","")IF(INDEX('MOA role matrix'!$B$2:$D$13,3,MATCH($B4,'MOA role matrix'!$B$1:$D$1,0))="If finance","CFO / Head of Finance (if finance), ","")IF(INDEX('MOA role matrix'!$B$2:$D$13,3,MATCH($B4,'MOA role matrix'!$B$1:$D$1,0))="Auto","CFO / Head of Finance (auto), ","")IF(INDEX('MOA role matrix'!$B$2:$D$13,4,MATCH($B4,'MOA role matrix'!$B$1:$D$1,0))="Fill","CEO / COO / GM, ","")IF(INDEX('MOA role matrix'!$B$2:$D$13,4,MATCH($B4,'MOA role matrix'!$B$1:$D$1,0))="If finance","CEO / COO / GM (if finance), ","")IF(INDEX('MOA role matrix'!$B$2:$D$13,4,MATCH($B4,'MOA role matrix'!$B$1:$D$1,0))="Auto","CEO / COO / GM (auto), ","")IF(INDEX('MOA role matrix'!$B$2:$D$13,5,MATCH($B4,'MOA role matrix'!$B$1:$D$1,0))="Fill","Board member 1, ","")IF(INDEX('MOA role matrix'!$B$2:$D$13,5,MATCH($B4,'MOA role matrix'!$B$1:$D$1,0))="If finance","Board member 1 (if finance), ","")IF(INDEX('MOA role matrix'!$B$2:$D$13,5,MATCH($B4,'MOA role matrix'!$B$1:$D$1,0))="Auto","Board member 1 (auto), ","")IF(INDEX('MOA role matrix'!$B$2:$D$13,6,MATCH($B4,'MOA role matrix'!$B$1:$D$1,0))="Fill","Board member 2, ","")IF(INDEX('MOA role matrix'!$B$2:$D$13,6,MATCH($B4,'MOA role matrix'!$B$1:$D$1,0))="If finance","Board member 2 (if finance), ","")IF(INDEX('MOA role matrix'!$B$2:$D$13,6,MATCH($B4,'MOA role matrix'!$B$1:$D$1,0))="Auto","Board member 2 (auto), ","")IF(INDEX('MOA role matrix'!$B$2:$D$13,7,MATCH($B4,'MOA role matrix'!$B$1:$D$1,0))="Fill","LOA holder 1, ","")IF(INDEX('MOA role matrix'!$B$2:$D$13,7,MATCH($B4,'MOA role matrix'!$B$1:$D$1,0))="If finance","LOA holder 1 (if finance), ","")IF(INDEX('MOA role matrix'!$B$2:$D$13,7,MATCH($B4,'MOA role matrix'!$B$1:$D$1,0))="Auto","LOA holder 1 (auto), ","")IF(INDEX('MOA role matrix'!$B$2:$D$13,8,MATCH($B4,'MOA role matrix'!$B$1:$D$1,0))="Fill","LOA holder 2, ","")IF(INDEX('MOA role matrix'!$B$2:$D$13,8,MATCH($B4,'MOA role matrix'!$B$1:$D$1,0))="If finance","LOA holder 2 (if finance), ","")IF(INDEX('MOA role matrix'!$B$2:$D$13,8,MATCH($B4,'MOA role matrix'!$B$1:$D$1,0))="Auto","LOA holder 2 (auto), ","")IF(INDEX('MOA role matrix'!$B$2:$D$13,9,MATCH($B4,'MOA role matrix'!$B$1:$D$1,0))="Fill","Senior Manager CoSec, ","")IF(INDEX('MOA role matrix'!$B$2:$D$13,9,MATCH($B4,'MOA role matrix'!$B$1:$D$1,0))="If finance","Senior Manager CoSec (if finance), ","")IF(INDEX('MOA role matrix'!$B$2:$D$13,9,MATCH($B4,'MOA role matrix'!$B$1:$D$1,0))="Auto","Senior Manager CoSec (auto), ","")IF(INDEX('MOA role matrix'!$B$2:$D$13,10,MATCH($B4,'MOA role matrix'!$B$1:$D$1,0))="Fill","Division MOI managers, ","")IF(INDEX('MOA role matrix'!$B$2:$D$13,10,MATCH($B4,'MOA role matrix'!$B$1:$D$1,0))="If finance","Division MOI managers (if finance), ","")IF(INDEX('MOA role matrix'!$B$2:$D$13,10,MATCH($B4,'MOA role matrix'!$B$1:$D$1,0))="Auto","Division MOI managers (auto), ","")IF(INDEX('MOA role matrix'!$B$2:$D$13,11,MATCH($B4,'MOA role matrix'!$B$1:$D$1,0))="Fill","Ms Teh (bank), ","")IF(INDEX('MOA role matrix'!$B$2:$D$13,11,MATCH($B4,'MOA role matrix'!$B$1:$D$1,0))="If finance","Ms Teh (bank) (if finance), ","")IF(INDEX('MOA role matrix'!$B$2:$D$13,11,MATCH($B4,'MOA role matrix'!$B$1:$D$1,0))="Auto","Ms Teh (bank) (auto), ","")IF(INDEX('MOA role matrix'!$B$2:$D$13,12,MATCH($B4,'MOA role matrix'!$B$1:$D$1,0))="Fill","DLCM, ","")IF(INDEX('MOA role matrix'!$B$2:$D$13,12,MATCH($B4,'MOA role matrix'!$B$1:$D$1,0))="If finance","DLCM (if finance), ","")IF(INDEX('MOA role matrix'!$B$2:$D$13,12,MATCH($B4,'MOA role matrix'!$B$1:$D$1,0))="Auto","DLCM (auto), ",""))) | D4: =IF($A4="","",IFERROR(INDEX(FILTER('Client contacts'!$B$2:$B$500,('Client contacts'!$A$2:$A$500=$A4)*('Client contacts'!$H$2:$H$500="Y"),""),1),"")) | E4: =IF($A4="","",IFERROR(INDEX(FILTER('Client contacts'!$C$2:$C$500,('Client contacts'!$A$2:$A$500=$A4)*('Client contacts'!$H$2:$H$500="Y"),""),1),"")) | F4: =IF($A4="","",IFERROR(INDEX(FILTER('Client contacts'!$B$2:$B$500,('Client contacts'!$A$2:$A$500=$A4)*('Client contacts'!$G$2:$G$500="Y"),""),1),"")) | G4: =IF($A4="","",IFERROR(INDEX(FILTER('Client contacts'!$C$2:$C$500,('Client contacts'!$A$2:$A$500=$A4)*('Client contacts'!$G$2:$G$500="Y"),""),1),"")) | H4: =IF($A4="","",IFERROR(INDEX(FILTER('Client contacts'!$B$2:$B$500,('Client contacts'!$A$2:$A$500=$A4)*('Client contacts'!$G$2:$G$500="Y"),""),2),"")) | I4: =IF($A4="","",IFERROR(INDEX(FILTER('Client contacts'!$C$2:$C$500,('Client contacts'!$A$2:$A$500=$A4)*('Client contacts'!$G$2:$G$500="Y"),""),2),"")) | R4: =IF($A4="","",IFERROR(INDEX(Companies!$I$2:$I$500,MATCH($A4,Companies!$A$2:$A$500,0)),""))
C5: =IF($B5="","",TRIM(IF(INDEX('MOA role matrix'!$B$2:$D$13,1,MATCH($B5,'MOA role matrix'!$B$1:$D$1,0))="Fill","Project initiator, ","")IF(INDEX('MOA role matrix'!$B$2:$D$13,1,MATCH($B5,'MOA role matrix'!$B$1:$D$1,0))="If finance","Project initiator (if finance), ","")IF(INDEX('MOA role matrix'!$B$2:$D$13,1,MATCH($B5,'MOA role matrix'!$B$1:$D$1,0))="Auto","Project initiator (auto), ","")IF(INDEX('MOA role matrix'!$B$2:$D$13,2,MATCH($B5,'MOA role matrix'!$B$1:$D$1,0))="Fill","MOA signers (client), ","")IF(INDEX('MOA role matrix'!$B$2:$D$13,2,MATCH($B5,'MOA role matrix'!$B$1:$D$1,0))="If finance","MOA signers (client) (if finance), ","")IF(INDEX('MOA role matrix'!$B$2:$D$13,2,MATCH($B5,'MOA role matrix'!$B$1:$D$1,0))="Auto","MOA signers (client) (auto), ","")IF(INDEX('MOA role matrix'!$B$2:$D$13,3,MATCH($B5,'MOA role matrix'!$B$1:$D$1,0))="Fill","CFO / Head of Finance, ","")IF(INDEX('MOA role matrix'!$B$2:$D$13,3,MATCH($B5,'MOA role matrix'!$B$1:$D$1,0))="If finance","CFO / Head of Finance (if finance), ","")IF(INDEX('MOA role matrix'!$B$2:$D$13,3,MATCH($B5,'MOA role matrix'!$B$1:$D$1,0))="Auto","CFO / Head of Finance (auto), ","")IF(INDEX('MOA role matrix'!$B$2:$D$13,4,MATCH($B5,'MOA role matrix'!$B$1:$D$1,0))="Fill","CEO / COO / GM, ","")IF(INDEX('MOA role matrix'!$B$2:$D$13,4,MATCH($B5,'MOA role matrix'!$B$1:$D$1,0))="If finance","CEO / COO / GM (if finance), ","")IF(INDEX('MOA role matrix'!$B$2:$D$13,4,MATCH($B5,'MOA role matrix'!$B$1:$D$1,0))="Auto","CEO / COO / GM (auto), ","")IF(INDEX('MOA role matrix'!$B$2:$D$13,5,MATCH($B5,'MOA role matrix'!$B$1:$D$1,0))="Fill","Board member 1, ","")IF(INDEX('MOA role matrix'!$B$2:$D$13,5,MATCH($B5,'MOA role matrix'!$B$1:$D$1,0))="If finance","Board member 1 (if finance), ","")IF(INDEX('MOA role matrix'!$B$2:$D$13,5,MATCH($B5,'MOA role matrix'!$B$1:$D$1,0))="Auto","Board member 1 (auto), ","")IF(INDEX('MOA role matrix'!$B$2:$D$13,6,MATCH($B5,'MOA role matrix'!$B$1:$D$1,0))="Fill","Board member 2, ","")IF(INDEX('MOA role matrix'!$B$2:$D$13,6,MATCH($B5,'MOA role matrix'!$B$1:$D$1,0))="If finance","Board member 2 (if finance), ","")IF(INDEX('MOA role matrix'!$B$2:$D$13,6,MATCH($B5,'MOA role matrix'!$B$1:$D$1,0))="Auto","Board member 2 (auto), ","")IF(INDEX('MOA role matrix'!$B$2:$D$13,7,MATCH($B5,'MOA role matrix'!$B$1:$D$1,0))="Fill","LOA holder 1, ","")IF(INDEX('MOA role matrix'!$B$2:$D$13,7,MATCH($B5,'MOA role matrix'!$B$1:$D$1,0))="If finance","LOA holder 1 (if finance), ","")IF(INDEX('MOA role matrix'!$B$2:$D$13,7,MATCH($B5,'MOA role matrix'!$B$1:$D$1,0))="Auto","LOA holder 1 (auto), ","")IF(INDEX('MOA role matrix'!$B$2:$D$13,8,MATCH($B5,'MOA role matrix'!$B$1:$D$1,0))="Fill","LOA holder 2, ","")IF(INDEX('MOA role matrix'!$B$2:$D$13,8,MATCH($B5,'MOA role matrix'!$B$1:$D$1,0))="If finance","LOA holder 2 (if finance), ","")IF(INDEX('MOA role matrix'!$B$2:$D$13,8,MATCH($B5,'MOA role matrix'!$B$1:$D$1,0))="Auto","LOA holder 2 (auto), ","")IF(INDEX('MOA role matrix'!$B$2:$D$13,9,MATCH($B5,'MOA role matrix'!$B$1:$D$1,0))="Fill","Senior Manager CoSec, ","")IF(INDEX('MOA role matrix'!$B$2:$D$13,9,MATCH($B5,'MOA role matrix'!$B$1:$D$1,0))="If finance","Senior Manager CoSec (if finance), ","")IF(INDEX('MOA role matrix'!$B$2:$D$13,9,MATCH($B5,'MOA role matrix'!$B$1:$D$1,0))="Auto","Senior Manager CoSec (auto), ","")IF(INDEX('MOA role matrix'!$B$2:$D$13,10,MATCH($B5,'MOA role matrix'!$B$1:$D$1,0))="Fill","Division MOI managers, ","")IF(INDEX('MOA role matrix'!$B$2:$D$13,10,MATCH($B5,'MOA role matrix'!$B$1:$D$1,0))="If finance","Division MOI managers (if finance), ","")IF(INDEX('MOA role matrix'!$B$2:$D$13,10,MATCH($B5,'MOA role matrix'!$B$1:$D$1,0))="Auto","Division MOI managers (auto), ","")IF(INDEX('MOA role matrix'!$B$2:$D$13,11,MATCH($B5,'MOA role matrix'!$B$1:$D$1,0))="Fill","Ms Teh (bank), ","")IF(INDEX('MOA role matrix'!$B$2:$D$13,11,MATCH($B5,'MOA role matrix'!$B$1:$D$1,0))="If finance","Ms Teh (bank) (if finance), ","")IF(INDEX('MOA role matrix'!$B$2:$D$13,11,MATCH($B5,'MOA role matrix'!$B$1:$D$1,0))="Auto","Ms Teh (bank) (auto), ","")IF(INDEX('MOA role matrix'!$B$2:$D$13,12,MATCH($B5,'MOA role matrix'!$B$1:$D$1,0))="Fill","DLCM, ","")IF(INDEX('MOA role matrix'!$B$2:$D$13,12,MATCH($B5,'MOA role matrix'!$B$1:$D$1,0))="If finance","DLCM (if finance), ","")IF(INDEX('MOA role matrix'!$B$2:$D$13,12,MATCH($B5,'MOA role matrix'!$B$1:$D$1,0))="Auto","DLCM (auto), ",""))) | D5: =IF($A5="","",IFERROR(INDEX(FILTER('Client contacts'!$B$2:$B$500,('Client contacts'!$A$2:$A$500=$A5)*('Client contacts'!$H$2:$H$500="Y"),""),1),"")) | E5: =IF($A5="","",IFERROR(INDEX(FILTER('Client contacts'!$C$2:$C$500,('Client contacts'!$A$2:$A$500=$A5)*('Client contacts'!$H$2:$H$500="Y"),""),1),"")) | F5: =IF($A5="","",IFERROR(INDEX(FILTER('Client contacts'!$B$2:$B$500,('Client contacts'!$A$2:$A$500=$A5)*('Client contacts'!$G$2:$G$500="Y"),""),1),"")) | G5: =IF($A5="","",IFERROR(INDEX(FILTER('Client contacts'!$C$2:$C$500,('Client contacts'!$A$2:$A$500=$A5)*('Client contacts'!$G$2:$G$500="Y"),""),1),"")) | H5: =IF($A5="","",IFERROR(INDEX(FILTER('Client contacts'!$B$2:$B$500,('Client contacts'!$A$2:$A$500=$A5)*('Client contacts'!$G$2:$G$500="Y"),""),2),"")) | I5: =IF($A5="","",IFERROR(INDEX(FILTER('Client contacts'!$C$2:$C$500,('Client contacts'!$A$2:$A$500=$A5)*('Client contacts'!$G$2:$G$500="Y"),""),2),"")) | R5: =IF($A5="","",IFERROR(INDEX(Companies!$I$2:$I$500,MATCH($A5,Companies!$A$2:$A$500,0)),""))
C6: =IF($B6="","",TRIM(IF(INDEX('MOA role matrix'!$B$2:$D$13,1,MATCH($B6,'MOA role matrix'!$B$1:$D$1,0))="Fill","Project initiator, ","")IF(INDEX('MOA role matrix'!$B$2:$D$13,1,MATCH($B6,'MOA role matrix'!$B$1:$D$1,0))="If finance","Project initiator (if finance), ","")IF(INDEX('MOA role matrix'!$B$2:$D$13,1,MATCH($B6,'MOA role matrix'!$B$1:$D$1,0))="Auto","Project initiator (auto), ","")IF(INDEX('MOA role matrix'!$B$2:$D$13,2,MATCH($B6,'MOA role matrix'!$B$1:$D$1,0))="Fill","MOA signers (client), ","")IF(INDEX('MOA role matrix'!$B$2:$D$13,2,MATCH($B6,'MOA role matrix'!$B$1:$D$1,0))="If finance","MOA signers (client) (if finance), ","")IF(INDEX('MOA role matrix'!$B$2:$D$13,2,MATCH($B6,'MOA role matrix'!$B$1:$D$1,0))="Auto","MOA signers (client) (auto), ","")IF(INDEX('MOA role matrix'!$B$2:$D$13,3,MATCH($B6,'MOA role matrix'!$B$1:$D$1,0))="Fill","CFO / Head of Finance, ","")IF(INDEX('MOA role matrix'!$B$2:$D$13,3,MATCH($B6,'MOA role matrix'!$B$1:$D$1,0))="If finance","CFO / Head of Finance (if finance), ","")IF(INDEX('MOA role matrix'!$B$2:$D$13,3,MATCH($B6,'MOA role matrix'!$B$1:$D$1,0))="Auto","CFO / Head of Finance (auto), ","")IF(INDEX('MOA role matrix'!$B$2:$D$13,4,MATCH($B6,'MOA role matrix'!$B$1:$D$1,0))="Fill","CEO / COO / GM, ","")IF(INDEX('MOA role matrix'!$B$2:$D$13,4,MATCH($B6,'MOA role matrix'!$B$1:$D$1,0))="If finance","CEO / COO / GM (if finance), ","")IF(INDEX('MOA role matrix'!$B$2:$D$13,4,MATCH($B6,'MOA role matrix'!$B$1:$D$1,0))="Auto","CEO / COO / GM (auto), ","")IF(INDEX('MOA role matrix'!$B$2:$D$13,5,MATCH($B6,'MOA role matrix'!$B$1:$D$1,0))="Fill","Board member 1, ","")IF(INDEX('MOA role matrix'!$B$2:$D$13,5,MATCH($B6,'MOA role matrix'!$B$1:$D$1,0))="If finance","Board member 1 (if finance), ","")IF(INDEX('MOA role matrix'!$B$2:$D$13,5,MATCH($B6,'MOA role matrix'!$B$1:$D$1,0))="Auto","Board member 1 (auto), ","")IF(INDEX('MOA role matrix'!$B$2:$D$13,6,MATCH($B6,'MOA role matrix'!$B$1:$D$1,0))="Fill","Board member 2, ","")IF(INDEX('MOA role matrix'!$B$2:$D$13,6,MATCH($B6,'MOA role matrix'!$B$1:$D$1,0))="If finance","Board member 2 (if finance), ","")IF(INDEX('MOA role matrix'!$B$2:$D$13,6,MATCH($B6,'MOA role matrix'!$B$1:$D$1,0))="Auto","Board member 2 (auto), ","")IF(INDEX('MOA role matrix'!$B$2:$D$13,7,MATCH($B6,'MOA role matrix'!$B$1:$D$1,0))="Fill","LOA holder 1, ","")IF(INDEX('MOA role matrix'!$B$2:$D$13,7,MATCH($B6,'MOA role matrix'!$B$1:$D$1,0))="If finance","LOA holder 1 (if finance), ","")IF(INDEX('MOA role matrix'!$B$2:$D$13,7,MATCH($B6,'MOA role matrix'!$B$1:$D$1,0))="Auto","LOA holder 1 (auto), ","")IF(INDEX('MOA role matrix'!$B$2:$D$13,8,MATCH($B6,'MOA role matrix'!$B$1:$D$1,0))="Fill","LOA holder 2, ","")IF(INDEX('MOA role matrix'!$B$2:$D$13,8,MATCH($B6,'MOA role matrix'!$B$1:$D$1,0))="If finance","LOA holder 2 (if finance), ","")IF(INDEX('MOA role matrix'!$B$2:$D$13,8,MATCH($B6,'MOA role matrix'!$B$1:$D$1,0))="Auto","LOA holder 2 (auto), ","")IF(INDEX('MOA role matrix'!$B$2:$D$13,9,MATCH($B6,'MOA role matrix'!$B$1:$D$1,0))="Fill","Senior Manager CoSec, ","")IF(INDEX('MOA role matrix'!$B$2:$D$13,9,MATCH($B6,'MOA role matrix'!$B$1:$D$1,0))="If finance","Senior Manager CoSec (if finance), ","")IF(INDEX('MOA role matrix'!$B$2:$D$13,9,MATCH($B6,'MOA role matrix'!$B$1:$D$1,0))="Auto","Senior Manager CoSec (auto), ","")IF(INDEX('MOA role matrix'!$B$2:$D$13,10,MATCH($B6,'MOA role matrix'!$B$1:$D$1,0))="Fill","Division MOI managers, ","")IF(INDEX('MOA role matrix'!$B$2:$D$13,10,MATCH($B6,'MOA role matrix'!$B$1:$D$1,0))="If finance","Division MOI managers (if finance), ","")IF(INDEX('MOA role matrix'!$B$2:$D$13,10,MATCH($B6,'MOA role matrix'!$B$1:$D$1,0))="Auto","Division MOI managers (auto), ","")IF(INDEX('MOA role matrix'!$B$2:$D$13,11,MATCH($B6,'MOA role matrix'!$B$1:$D$1,0))="Fill","Ms Teh (bank), ","")IF(INDEX('MOA role matrix'!$B$2:$D$13,11,MATCH($B6,'MOA role matrix'!$B$1:$D$1,0))="If finance","Ms Teh (bank) (if finance), ","")IF(INDEX('MOA role matrix'!$B$2:$D$13,11,MATCH($B6,'MOA role matrix'!$B$1:$D$1,0))="Auto","Ms Teh (bank) (auto), ","")IF(INDEX('MOA role matrix'!$B$2:$D$13,12,MATCH($B6,'MOA role matrix'!$B$1:$D$1,0))="Fill","DLCM, ","")IF(INDEX('MOA role matrix'!$B$2:$D$13,12,MATCH($B6,'MOA role matrix'!$B$1:$D$1,0))="If finance","DLCM (if finance), ","")IF(INDEX('MOA role matrix'!$B$2:$D$13,12,MATCH($B6,'MOA role matrix'!$B$1:$D$1,0))="Auto","DLCM (auto), ",""))) | D6: =IF($A6="","",IFERROR(INDEX(FILTER('Client contacts'!$B$2:$B$500,('Client contacts'!$A$2:$A$500=$A6)*('Client contacts'!$H$2:$H$500="Y"),""),1),"")) | E6: =IF($A6="","",IFERROR(INDEX(FILTER('Client contacts'!$C$2:$C$500,('Client contacts'!$A$2:$A$500=$A6)*('Client contacts'!$H$2:$H$500="Y"),""),1),"")) | F6: =IF($A6="","",IFERROR(INDEX(FILTER('Client contacts'!$B$2:$B$500,('Client contacts'!$A$2:$A$500=$A6)*('Client contacts'!$G$2:$G$500="Y"),""),1),"")) | G6: =IF($A6="","",IFERROR(INDEX(FILTER('Client contacts'!$C$2:$C$500,('Client contacts'!$A$2:$A$500=$A6)*('Client contacts'!$G$2:$G$500="Y"),""),1),"")) | H6: =IF($A6="","",IFERROR(INDEX(FILTER('Client contacts'!$B$2:$B$500,('Client contacts'!$A$2:$A$500=$A6)*('Client contacts'!$G$2:$G$500="Y"),""),2),"")) | I6: =IF($A6="","",IFERROR(INDEX(FILTER('Client contacts'!$C$2:$C$500,('Client contacts'!$A$2:$A$500=$A6)*('Client contacts'!$G$2:$G$500="Y"),""),2),"")) | R6: =IF($A6="","",IFERROR(INDEX(Companies!$I$2:$I$500,MATCH($A6,Companies!$A$2:$A$500,0)),""))
C7: =IF($B7="","",TRIM(IF(INDEX('MOA role matrix'!$B$2:$D$13,1,MATCH($B7,'MOA role matrix'!$B$1:$D$1,0))="Fill","Project initiator, ","")IF(INDEX('MOA role matrix'!$B$2:$D$13,1,MATCH($B7,'MOA role matrix'!$B$1:$D$1,0))="If finance","Project initiator (if finance), ","")IF(INDEX('MOA role matrix'!$B$2:$D$13,1,MATCH($B7,'MOA role matrix'!$B$1:$D$1,0))="Auto","Project initiator (auto), ","")IF(INDEX('MOA role matrix'!$B$2:$D$13,2,MATCH($B7,'MOA role matrix'!$B$1:$D$1,0))="Fill","MOA signers (client), ","")IF(INDEX('MOA role matrix'!$B$2:$D$13,2,MATCH($B7,'MOA role matrix'!$B$1:$D$1,0))="If finance","MOA signers (client) (if finance), ","")IF(INDEX('MOA role matrix'!$B$2:$D$13,2,MATCH($B7,'MOA role matrix'!$B$1:$D$1,0))="Auto","MOA signers (client) (auto), ","")IF(INDEX('MOA role matrix'!$B$2:$D$13,3,MATCH($B7,'MOA role matrix'!$B$1:$D$1,0))="Fill","CFO / Head of Finance, ","")IF(INDEX('MOA role matrix'!$B$2:$D$13,3,MATCH($B7,'MOA role matrix'!$B$1:$D$1,0))="If finance","CFO / Head of Finance (if finance), ","")IF(INDEX('MOA role matrix'!$B$2:$D$13,3,MATCH($B7,'MOA role matrix'!$B$1:$D$1,0))="Auto","CFO / Head of Finance (auto), ","")IF(INDEX('MOA role matrix'!$B$2:$D$13,4,MATCH($B7,'MOA role matrix'!$B$1:$D$1,0))="Fill","CEO / COO / GM, ","")IF(INDEX('MOA role matrix'!$B$2:$D$13,4,MATCH($B7,'MOA role matrix'!$B$1:$D$1,0))="If finance","CEO / COO / GM (if finance), ","")IF(INDEX('MOA role matrix'!$B$2:$D$13,4,MATCH($B7,'MOA role matrix'!$B$1:$D$1,0))="Auto","CEO / COO / GM (auto), ","")IF(INDEX('MOA role matrix'!$B$2:$D$13,5,MATCH($B7,'MOA role matrix'!$B$1:$D$1,0))="Fill","Board member 1, ","")IF(INDEX('MOA role matrix'!$B$2:$D$13,5,MATCH($B7,'MOA role matrix'!$B$1:$D$1,0))="If finance","Board member 1 (if finance), ","")IF(INDEX('MOA role matrix'!$B$2:$D$13,5,MATCH($B7,'MOA role matrix'!$B$1:$D$1,0))="Auto","Board member 1 (auto), ","")IF(INDEX('MOA role matrix'!$B$2:$D$13,6,MATCH($B7,'MOA role matrix'!$B$1:$D$1,0))="Fill","Board member 2, ","")IF(INDEX('MOA role matrix'!$B$2:$D$13,6,MATCH($B7,'MOA role matrix'!$B$1:$D$1,0))="If finance","Board member 2 (if finance), ","")IF(INDEX('MOA role matrix'!$B$2:$D$13,6,MATCH($B7,'MOA role matrix'!$B$1:$D$1,0))="Auto","Board member 2 (auto), ","")IF(INDEX('MOA role matrix'!$B$2:$D$13,7,MATCH($B7,'MOA role matrix'!$B$1:$D$1,0))="Fill","LOA holder 1, ","")IF(INDEX('MOA role matrix'!$B$2:$D$13,7,MATCH($B7,'MOA role matrix'!$B$1:$D$1,0))="If finance","LOA holder 1 (if finance), ","")IF(INDEX('MOA role matrix'!$B$2:$D$13,7,MATCH($B7,'MOA role matrix'!$B$1:$D$1,0))="Auto","LOA holder 1 (auto), ","")IF(INDEX('MOA role matrix'!$B$2:$D$13,8,MATCH($B7,'MOA role matrix'!$B$1:$D$1,0))="Fill","LOA holder 2, ","")IF(INDEX('MOA role matrix'!$B$2:$D$13,8,MATCH($B7,'MOA role matrix'!$B$1:$D$1,0))="If finance","LOA holder 2 (if finance), ","")IF(INDEX('MOA role matrix'!$B$2:$D$13,8,MATCH($B7,'MOA role matrix'!$B$1:$D$1,0))="Auto","LOA holder 2 (auto), ","")IF(INDEX('MOA role matrix'!$B$2:$D$13,9,MATCH($B7,'MOA role matrix'!$B$1:$D$1,0))="Fill","Senior Manager CoSec, ","")IF(INDEX('MOA role matrix'!$B$2:$D$13,9,MATCH($B7,'MOA role matrix'!$B$1:$D$1,0))="If finance","Senior Manager CoSec (if finance), ","")IF(INDEX('MOA role matrix'!$B$2:$D$13,9,MATCH($B7,'MOA role matrix'!$B$1:$D$1,0))="Auto","Senior Manager CoSec (auto), ","")IF(INDEX('MOA role matrix'!$B$2:$D$13,10,MATCH($B7,'MOA role matrix'!$B$1:$D$1,0))="Fill","Division MOI managers, ","")IF(INDEX('MOA role matrix'!$B$2:$D$13,10,MATCH($B7,'MOA role matrix'!$B$1:$D$1,0))="If finance","Division MOI managers (if finance), ","")IF(INDEX('MOA role matrix'!$B$2:$D$13,10,MATCH($B7,'MOA role matrix'!$B$1:$D$1,0))="Auto","Division MOI managers (auto), ","")IF(INDEX('MOA role matrix'!$B$2:$D$13,11,MATCH($B7,'MOA role matrix'!$B$1:$D$1,0))="Fill","Ms Teh (bank), ","")IF(INDEX('MOA role matrix'!$B$2:$D$13,11,MATCH($B7,'MOA role matrix'!$B$1:$D$1,0))="If finance","Ms Teh (bank) (if finance), ","")IF(INDEX('MOA role matrix'!$B$2:$D$13,11,MATCH($B7,'MOA role matrix'!$B$1:$D$1,0))="Auto","Ms Teh (bank) (auto), ","")IF(INDEX('MOA role matrix'!$B$2:$D$13,12,MATCH($B7,'MOA role matrix'!$B$1:$D$1,0))="Fill","DLCM, ","")IF(INDEX('MOA role matrix'!$B$2:$D$13,12,MATCH($B7,'MOA role matrix'!$B$1:$D$1,0))="If finance","DLCM (if finance), ","")IF(INDEX('MOA role matrix'!$B$2:$D$13,12,MATCH($B7,'MOA role matrix'!$B$1:$D$1,0))="Auto","DLCM (auto), ",""))) | D7: =IF($A7="","",IFERROR(INDEX(FILTER('Client contacts'!$B$2:$B$500,('Client contacts'!$A$2:$A$500=$A7)*('Client contacts'!$H$2:$H$500="Y"),""),1),"")) | E7: =IF($A7="","",IFERROR(INDEX(FILTER('Client contacts'!$C$2:$C$500,('Client contacts'!$A$2:$A$500=$A7)*('Client contacts'!$H$2:$H$500="Y"),""),1),"")) | F7: =IF($A7="","",IFERROR(INDEX(FILTER('Client contacts'!$B$2:$B$500,('Client contacts'!$A$2:$A$500=$A7)*('Client contacts'!$G$2:$G$500="Y"),""),1),"")) | G7: =IF($A7="","",IFERROR(INDEX(FILTER('Client contacts'!$C$2:$C$500,('Client contacts'!$A$2:$A$500=$A7)*('Client contacts'!$G$2:$G$500="Y"),""),1),"")) | H7: =IF($A7="","",IFERROR(INDEX(FILTER('Client contacts'!$B$2:$B$500,('Client contacts'!$A$2:$A$500=$A7)*('Client contacts'!$G$2:$G$500="Y"),""),2),"")) | I7: =IF($A7="","",IFERROR(INDEX(FILTER('Client contacts'!$C$2:$C$500,('Client contacts'!$A$2:$A$500=$A7)*('Client contacts'!$G$2:$G$500="Y"),""),2),"")) | R7: =IF($A7="","",IFERROR(INDEX(Companies!$I$2:$I$500,MATCH($A7,Companies!$A$2:$A$500,0)),""))
C8: =IF($B8="","",TRIM(IF(INDEX('MOA role matrix'!$B$2:$D$13,1,MATCH($B8,'MOA role matrix'!$B$1:$D$1,0))="Fill","Project initiator, ","")IF(INDEX('MOA role matrix'!$B$2:$D$13,1,MATCH($B8,'MOA role matrix'!$B$1:$D$1,0))="If finance","Project initiator (if finance), ","")IF(INDEX('MOA role matrix'!$B$2:$D$13,1,MATCH($B8,'MOA role matrix'!$B$1:$D$1,0))="Auto","Project initiator (auto), ","")IF(INDEX('MOA role matrix'!$B$2:$D$13,2,MATCH($B8,'MOA role matrix'!$B$1:$D$1,0))="Fill","MOA signers (client), ","")IF(INDEX('MOA role matrix'!$B$2:$D$13,2,MATCH($B8,'MOA role matrix'!$B$1:$D$1,0))="If finance","MOA signers (client) (if finance), ","")IF(INDEX('MOA role matrix'!$B$2:$D$13,2,MATCH($B8,'MOA role matrix'!$B$1:$D$1,0))="Auto","MOA signers (client) (auto), ","")IF(INDEX('MOA role matrix'!$B$2:$D$13,3,MATCH($B8,'MOA role matrix'!$B$1:$D$1,0))="Fill","CFO / Head of Finance, ","")IF(INDEX('MOA role matrix'!$B$2:$D$13,3,MATCH($B8,'MOA role matrix'!$B$1:$D$1,0))="If finance","CFO / Head of Finance (if finance), ","")IF(INDEX('MOA role matrix'!$B$2:$D$13,3,MATCH($B8,'MOA role matrix'!$B$1:$D$1,0))="Auto","CFO / Head of Finance (auto), ","")IF(INDEX('MOA role matrix'!$B$2:$D$13,4,MATCH($B8,'MOA role matrix'!$B$1:$D$1,0))="Fill","CEO / COO / GM, ","")IF(INDEX('MOA role matrix'!$B$2:$D$13,4,MATCH($B8,'MOA role matrix'!$B$1:$D$1,0))="If finance","CEO / COO / GM (if finance), ","")IF(INDEX('MOA role matrix'!$B$2:$D$13,4,MATCH($B8,'MOA role matrix'!$B$1:$D$1,0))="Auto","CEO / COO / GM (auto), ","")IF(INDEX('MOA role matrix'!$B$2:$D$13,5,MATCH($B8,'MOA role matrix'!$B$1:$D$1,0))="Fill","Board member 1, ","")IF(INDEX('MOA role matrix'!$B$2:$D$13,5,MATCH($B8,'MOA role matrix'!$B$1:$D$1,0))="If finance","Board member 1 (if finance), ","")IF(INDEX('MOA role matrix'!$B$2:$D$13,5,MATCH($B8,'MOA role matrix'!$B$1:$D$1,0))="Auto","Board member 1 (auto), ","")IF(INDEX('MOA role matrix'!$B$2:$D$13,6,MATCH($B8,'MOA role matrix'!$B$1:$D$1,0))="Fill","Board member 2, ","")IF(INDEX('MOA role matrix'!$B$2:$D$13,6,MATCH($B8,'MOA role matrix'!$B$1:$D$1,0))="If finance","Board member 2 (if finance), ","")IF(INDEX('MOA role matrix'!$B$2:$D$13,6,MATCH($B8,'MOA role matrix'!$B$1:$D$1,0))="Auto","Board member 2 (auto), ","")IF(INDEX('MOA role matrix'!$B$2:$D$13,7,MATCH($B8,'MOA role matrix'!$B$1:$D$1,0))="Fill","LOA holder 1, ","")IF(INDEX('MOA role matrix'!$B$2:$D$13,7,MATCH($B8,'MOA role matrix'!$B$1:$D$1,0))="If finance","LOA holder 1 (if finance), ","")IF(INDEX('MOA role matrix'!$B$2:$D$13,7,MATCH($B8,'MOA role matrix'!$B$1:$D$1,0))="Auto","LOA holder 1 (auto), ","")IF(INDEX('MOA role matrix'!$B$2:$D$13,8,MATCH($B8,'MOA role matrix'!$B$1:$D$1,0))="Fill","LOA holder 2, ","")IF(INDEX('MOA role matrix'!$B$2:$D$13,8,MATCH($B8,'MOA role matrix'!$B$1:$D$1,0))="If finance","LOA holder 2 (if finance), ","")IF(INDEX('MOA role matrix'!$B$2:$D$13,8,MATCH($B8,'MOA role matrix'!$B$1:$D$1,0))="Auto","LOA holder 2 (auto), ","")IF(INDEX('MOA role matrix'!$B$2:$D$13,9,MATCH($B8,'MOA role matrix'!$B$1:$D$1,0))="Fill","Senior Manager CoSec, ","")IF(INDEX('MOA role matrix'!$B$2:$D$13,9,MATCH($B8,'MOA role matrix'!$B$1:$D$1,0))="If finance","Senior Manager CoSec (if finance), ","")IF(INDEX('MOA role matrix'!$B$2:$D$13,9,MATCH($B8,'MOA role matrix'!$B$1:$D$1,0))="Auto","Senior Manager CoSec (auto), ","")IF(INDEX('MOA role matrix'!$B$2:$D$13,10,MATCH($B8,'MOA role matrix'!$B$1:$D$1,0))="Fill","Division MOI managers, ","")IF(INDEX('MOA role matrix'!$B$2:$D$13,10,MATCH($B8,'MOA role matrix'!$B$1:$D$1,0))="If finance","Division MOI managers (if finance), ","")IF(INDEX('MOA role matrix'!$B$2:$D$13,10,MATCH($B8,'MOA role matrix'!$B$1:$D$1,0))="Auto","Division MOI managers (auto), ","")IF(INDEX('MOA role matrix'!$B$2:$D$13,11,MATCH($B8,'MOA role matrix'!$B$1:$D$1,0))="Fill","Ms Teh (bank), ","")IF(INDEX('MOA role matrix'!$B$2:$D$13,11,MATCH($B8,'MOA role matrix'!$B$1:$D$1,0))="If finance","Ms Teh (bank) (if finance), ","")IF(INDEX('MOA role matrix'!$B$2:$D$13,11,MATCH($B8,'MOA role matrix'!$B$1:$D$1,0))="Auto","Ms Teh (bank) (auto), ","")IF(INDEX('MOA role matrix'!$B$2:$D$13,12,MATCH($B8,'MOA role matrix'!$B$1:$D$1,0))="Fill","DLCM, ","")IF(INDEX('MOA role matrix'!$B$2:$D$13,12,MATCH($B8,'MOA role matrix'!$B$1:$D$1,0))="If finance","DLCM (if finance), ","")IF(INDEX('MOA role matrix'!$B$2:$D$13,12,MATCH($B8,'MOA role matrix'!$B$1:$D$1,0))="Auto","DLCM (auto), ",""))) | D8: =IF($A8="","",IFERROR(INDEX(FILTER('Client contacts'!$B$2:$B$500,('Client contacts'!$A$2:$A$500=$A8)*('Client contacts'!$H$2:$H$500="Y"),""),1),"")) | E8: =IF($A8="","",IFERROR(INDEX(FILTER('Client contacts'!$C$2:$C$500,('Client contacts'!$A$2:$A$500=$A8)*('Client contacts'!$H$2:$H$500="Y"),""),1),"")) | F8: =IF($A8="","",IFERROR(INDEX(FILTER('Client contacts'!$B$2:$B$500,('Client contacts'!$A$2:$A$500=$A8)*('Client contacts'!$G$2:$G$500="Y"),""),1),"")) | G8: =IF($A8="","",IFERROR(INDEX(FILTER('Client contacts'!$C$2:$C$500,('Client contacts'!$A$2:$A$500=$A8)*('Client contacts'!$G$2:$G$500="Y"),""),1),"")) | H8: =IF($A8="","",IFERROR(INDEX(FILTER('Client contacts'!$B$2:$B$500,('Client contacts'!$A$2:$A$500=$A8)*('Client contacts'!$G$2:$G$500="Y"),""),2),"")) | I8: =IF($A8="","",IFERROR(INDEX(FILTER('Client contacts'!$C$2:$C$500,('Client contacts'!$A$2:$A$500=$A8)*('Client contacts'!$G$2:$G$500="Y"),""),2),"")) | R8: =IF($A8="","",IFERROR(INDEX(Companies!$I$2:$I$500,MATCH($A8,Companies!$A$2:$A$500,0)),""))
C9: =IF($B9="","",TRIM(IF(INDEX('MOA role matrix'!$B$2:$D$13,1,MATCH($B9,'MOA role matrix'!$B$1:$D$1,0))="Fill","Project initiator, ","")IF(INDEX('MOA role matrix'!$B$2:$D$13,1,MATCH($B9,'MOA role matrix'!$B$1:$D$1,0))="If finance","Project initiator (if finance), ","")IF(INDEX('MOA role matrix'!$B$2:$D$13,1,MATCH($B9,'MOA role matrix'!$B$1:$D$1,0))="Auto","Project initiator (auto), ","")IF(INDEX('MOA role matrix'!$B$2:$D$13,2,MATCH($B9,'MOA role matrix'!$B$1:$D$1,0))="Fill","MOA signers (client), ","")IF(INDEX('MOA role matrix'!$B$2:$D$13,2,MATCH($B9,'MOA role matrix'!$B$1:$D$1,0))="If finance","MOA signers (client) (if finance), ","")IF(INDEX('MOA role matrix'!$B$2:$D$13,2,MATCH($B9,'MOA role matrix'!$B$1:$D$1,0))="Auto","MOA signers (client) (auto), ","")IF(INDEX('MOA role matrix'!$B$2:$D$13,3,MATCH($B9,'MOA role matrix'!$B$1:$D$1,0))="Fill","CFO / Head of Finance, ","")IF(INDEX('MOA role matrix'!$B$2:$D$13,3,MATCH($B9,'MOA role matrix'!$B$1:$D$1,0))="If finance","CFO / Head of Finance (if finance), ","")IF(INDEX('MOA role matrix'!$B$2:$D$13,3,MATCH($B9,'MOA role matrix'!$B$1:$D$1,0))="Auto","CFO / Head of Finance (auto), ","")IF(INDEX('MOA role matrix'!$B$2:$D$13,4,MATCH($B9,'MOA role matrix'!$B$1:$D$1,0))="Fill","CEO / COO / GM, ","")IF(INDEX('MOA role matrix'!$B$2:$D$13,4,MATCH($B9,'MOA role matrix'!$B$1:$D$1,0))="If finance","CEO / COO / GM (if finance), ","")IF(INDEX('MOA role matrix'!$B$2:$D$13,4,MATCH($B9,'MOA role matrix'!$B$1:$D$1,0))="Auto","CEO / COO / GM (auto), ","")IF(INDEX('MOA role matrix'!$B$2:$D$13,5,MATCH($B9,'MOA role matrix'!$B$1:$D$1,0))="Fill","Board member 1, ","")IF(INDEX('MOA role matrix'!$B$2:$D$13,5,MATCH($B9,'MOA role matrix'!$B$1:$D$1,0))="If finance","Board member 1 (if finance), ","")IF(INDEX('MOA role matrix'!$B$2:$D$13,5,MATCH($B9,'MOA role matrix'!$B$1:$D$1,0))="Auto","Board member 1 (auto), ","")IF(INDEX('MOA role matrix'!$B$2:$D$13,6,MATCH($B9,'MOA role matrix'!$B$1:$D$1,0))="Fill","Board member 2, ","")IF(INDEX('MOA role matrix'!$B$2:$D$13,6,MATCH($B9,'MOA role matrix'!$B$1:$D$1,0))="If finance","Board member 2 (if finance), ","")IF(INDEX('MOA role matrix'!$B$2:$D$13,6,MATCH($B9,'MOA role matrix'!$B$1:$D$1,0))="Auto","Board member 2 (auto), ","")IF(INDEX('MOA role matrix'!$B$2:$D$13,7,MATCH($B9,'MOA role matrix'!$B$1:$D$1,0))="Fill","LOA holder 1, ","")IF(INDEX('MOA role matrix'!$B$2:$D$13,7,MATCH($B9,'MOA role matrix'!$B$1:$D$1,0))="If finance","LOA holder 1 (if finance), ","")IF(INDEX('MOA role matrix'!$B$2:$D$13,7,MATCH($B9,'MOA role matrix'!$B$1:$D$1,0))="Auto","LOA holder 1 (auto), ","")IF(INDEX('MOA role matrix'!$B$2:$D$13,8,MATCH($B9,'MOA role matrix'!$B$1:$D$1,0))="Fill","LOA holder 2, ","")IF(INDEX('MOA role matrix'!$B$2:$D$13,8,MATCH($B9,'MOA role matrix'!$B$1:$D$1,0))="If finance","LOA holder 2 (if finance), ","")IF(INDEX('MOA role matrix'!$B$2:$D$13,8,MATCH($B9,'MOA role matrix'!$B$1:$D$1,0))="Auto","LOA holder 2 (auto), ","")IF(INDEX('MOA role matrix'!$B$2:$D$13,9,MATCH($B9,'MOA role matrix'!$B$1:$D$1,0))="Fill","Senior Manager CoSec, ","")IF(INDEX('MOA role matrix'!$B$2:$D$13,9,MATCH($B9,'MOA role matrix'!$B$1:$D$1,0))="If finance","Senior Manager CoSec (if finance), ","")IF(INDEX('MOA role matrix'!$B$2:$D$13,9,MATCH($B9,'MOA role matrix'!$B$1:$D$1,0))="Auto","Senior Manager CoSec (auto), ","")IF(INDEX('MOA role matrix'!$B$2:$D$13,10,MATCH($B9,'MOA role matrix'!$B$1:$D$1,0))="Fill","Division MOI managers, ","")IF(INDEX('MOA role matrix'!$B$2:$D$13,10,MATCH($B9,'MOA role matrix'!$B$1:$D$1,0))="If finance","Division MOI managers (if finance), ","")IF(INDEX('MOA role matrix'!$B$2:$D$13,10,MATCH($B9,'MOA role matrix'!$B$1:$D$1,0))="Auto","Division MOI managers (auto), ","")IF(INDEX('MOA role matrix'!$B$2:$D$13,11,MATCH($B9,'MOA role matrix'!$B$1:$D$1,0))="Fill","Ms Teh (bank), ","")IF(INDEX('MOA role matrix'!$B$2:$D$13,11,MATCH($B9,'MOA role matrix'!$B$1:$D$1,0))="If finance","Ms Teh (bank) (if finance), ","")IF(INDEX('MOA role matrix'!$B$2:$D$13,11,MATCH($B9,'MOA role matrix'!$B$1:$D$1,0))="Auto","Ms Teh (bank) (auto), ","")IF(INDEX('MOA role matrix'!$B$2:$D$13,12,MATCH($B9,'MOA role matrix'!$B$1:$D$1,0))="Fill","DLCM, ","")IF(INDEX('MOA role matrix'!$B$2:$D$13,12,MATCH($B9,'MOA role matrix'!$B$1:$D$1,0))="If finance","DLCM (if finance), ","")IF(INDEX('MOA role matrix'!$B$2:$D$13,12,MATCH($B9,'MOA role matrix'!$B$1:$D$1,0))="Auto","DLCM (auto), ",""))) | D9: =IF($A9="","",IFERROR(INDEX(FILTER('Client contacts'!$B$2:$B$500,('Client contacts'!$A$2:$A$500=$A9)*('Client contacts'!$H$2:$H$500="Y"),""),1),"")) | E9: =IF($A9="","",IFERROR(INDEX(FILTER('Client contacts'!$C$2:$C$500,('Client contacts'!$A$2:$A$500=$A9)*('Client contacts'!$H$2:$H$500="Y"),""),1),"")) | F9: =IF($A9="","",IFERROR(INDEX(FILTER('Client contacts'!$B$2:$B$500,('Client contacts'!$A$2:$A$500=$A9)*('Client contacts'!$G$2:$G$500="Y"),""),1),"")) | G9: =IF($A9="","",IFERROR(INDEX(FILTER('Client contacts'!$C$2:$C$500,('Client contacts'!$A$2:$A$500=$A9)*('Client contacts'!$G$2:$G$500="Y"),""),1),"")) | H9: =IF($A9="","",IFERROR(INDEX(FILTER('Client contacts'!$B$2:$B$500,('Client contacts'!$A$2:$A$500=$A9)*('Client contacts'!$G$2:$G$500="Y"),""),2),"")) | I9: =IF($A9="","",IFERROR(INDEX(FILTER('Client contacts'!$C$2:$C$500,('Client contacts'!$A$2:$A$500=$A9)*('Client contacts'!$G$2:$G$500="Y"),""),2),"")) | R9: =IF($A9="","",IFERROR(INDEX(Companies!$I$2:$I$500,MATCH($A9,Companies!$A$2:$A$500,0)),""))
